E
======================================================================
ERROR: test_small_prime (__main__.SieveTest)
----------------------------------------------------------------------
Traceback (most recent call last):
  File "/home/peters43/209_18S/admin/grading/a3/marking_scripts/test_helpers.py", line 161, in _t
    stdout, stderr, returncode = self._run_exec(args=args, input_=input_, timeout=timeout, check=check)
  File "/home/peters43/209_18S/admin/grading/a3/marking_scripts/test_helpers.py", line 101, in _run_exec
    **kwargs)
  File "/home/peters43/209_18S/admin/grading/a3/marking_scripts/test_helpers.py", line 496, in _exec
    shell=shell)
  File "/opt/anaconda3/lib/python3.6/subprocess.py", line 709, in __init__
    restore_signals, start_new_session)
  File "/opt/anaconda3/lib/python3.6/subprocess.py", line 1344, in _execute_child
    raise child_exception_type(errno_num, err_msg, err_filename)
FileNotFoundError: [Errno 2] No such file or directory: './pfact_fake': './pfact_fake'

----------------------------------------------------------------------
Ran 1 test in 0.003s

FAILED (errors=1)
