FFFFFF.F
======================================================================
FAIL: test_server_kill__no_running_jobs (__main__.TestServer)
Send the server kill with invalid PID. Receive "Job %d not found".
----------------------------------------------------------------------
Traceback (most recent call last):
  File "server_run_kill_test.py", line 86, in test_server_kill__no_running_jobs
    self.assertIn('[SERVER] Job 42 not found', stdoutput)
AssertionError: '[SERVER] Job 42 not found' not found in ''

======================================================================
FAIL: test_server_run__exec_with_args (__main__.TestServer)
Send the server "run" with arguments. Output must reflect arguments.
----------------------------------------------------------------------
Traceback (most recent call last):
  File "server_run_kill_test.py", line 77, in test_server_run__exec_with_args
    self.assertIn('Argument: ArgProvided', stdoutput)
AssertionError: 'Argument: ArgProvided' not found in ''

======================================================================
FAIL: test_server_run__exec_with_no_args (__main__.TestServer)
Send the server "run" with no arguments. Confirmation should be sent.
----------------------------------------------------------------------
Traceback (most recent call last):
  File "server_run_kill_test.py", line 35, in test_server_run__exec_with_no_args
    self.assertTrue(confirmation_found)
AssertionError: False is not true

======================================================================
FAIL: test_server_run__invalid_exec (__main__.TestServer)
Send the server "run" with invalid executable. Command should fail. (exec error.)
----------------------------------------------------------------------
Traceback (most recent call last):
  File "server_run_kill_test.py", line 21, in test_server_run__invalid_exec
    self.assertIn('not', stdoutput)
AssertionError: 'not' not found in ''

======================================================================
FAIL: test_server_run__job_termination_announced (__main__.TestServer)
Verify that job close is appropriately announced.
----------------------------------------------------------------------
Traceback (most recent call last):
  File "server_run_kill_test.py", line 69, in test_server_run__job_termination_announced
    self.assertIn('Exited with status 0', stdoutput)
AssertionError: 'Exited with status 0' not found in ''

======================================================================
FAIL: test_server_run__stderr_sent_to_client (__main__.TestServer)
Send the server "run", verify that output is sent to client.
----------------------------------------------------------------------
Traceback (most recent call last):
  File "server_run_kill_test.py", line 60, in test_server_run__stderr_sent_to_client
    self.assertIn(')*', stdoutput)
AssertionError: ')*' not found in ''

======================================================================
FAIL: test_server_run__stdout_sent_to_client (__main__.TestServer)
Send the server "run", verify that output is sent to client.
----------------------------------------------------------------------
Traceback (most recent call last):
  File "server_run_kill_test.py", line 43, in test_server_run__stdout_sent_to_client
    self.assertIn('Peter Piper', stdoutput)
AssertionError: 'Peter Piper' not found in ''

----------------------------------------------------------------------
Ran 8 tests in 8.068s

FAILED (failures=7)
